# Promise 的含义
1. Promise 是一个容器，里面保存着某个未来才会结束的事件的结果（通常是一个异步操作）
2. Promise 提供统一的 API，各种异步操作都可以用同样的方法进行处理。

# Promise对象的特点
1. Promise对象代表一个异步操作，有三种状态：pending 、resolve 和 rejected。
2. 对象的状态不受外界影响，只有异步操作的结果，可以决定当前是哪一种状态。
3. Promise对象的状态改变，只有两种可能：从pending变为resolve和从pending变为rejected。
4. Promise对象的状态一旦改变，就不会再变，任何时候都可以得到这个结果。

# Promise的优点
1. Promise 对象提供统一的接口，使得控制异步操作更加容易。
2. 如果改变已经发生了，你再对Promise对象添加回调函数，也会立即得到这个结果。
3. 这与事件（Event）完全不同，事件的特点是，如果你错过了它，再去监听，是得不到结果的。
4. Promise 可以将异步操作以同步操作的流程表达出来，避免了层层嵌套的回调函数。

# Promise的缺点
1. 无法取消Promise，一旦新建它就会立即执行，无法中途取消。
2. 如果不设置回调函数，Promise内部抛出的错误，不会反应到外部。
3. 当处于pending状态时，无法得知目前进展到哪一个阶段（刚刚开始还是即将完成）。

# 基本用法
1. Promise构造函数接受一个函数作为参数，该函数的两个参数分别是resolve和reject，它们是两个函数。
2. resolve函数的作用是，将Promise对象的状态从 pending 变为 resolved，在异步操作成功时调用，并将异步操作的结果，作为参数传递出去。
3. reject函数的作用是，将Promise对象的状态从 pending 变为 rejected，在异步操作失败时调用，并将异步操作报出的错误，作为参数传递出去。
4. Promise实例生成以后，可以用then方法分别指定resolved状态和rejected状态的回调函数
``` bash
const promise = new Promise(function(resolve, reject) {
  if (/* 异步操作成功 */){
    resolve(value);
  } else {
    reject(error);
  }
});
promise.then(function(value) {
  // success
}, function(error) {
  // failure
});
// then方法可以接受两个回调函数作为参数。
// 第一个回调函数是Promise对象的状态变为resolved时调用，
// 第二个回调函数是Promise对象的状态变为rejected时调用。
// 其中，第二个函数是可选的，不一定要提供。
// 这两个函数都接受Promise对象传出的值作为参数。

------------------------------------------------------------
let promise = new Promise(function(resolve, reject) {
  console.log('Promise');
  resolve();
});
promise.then(function() {
  console.log('resolved.');
});
console.log('Hi!');
// Promise
// Hi!
// resolved

// Promise新建后立即执行，所以首先输出的是Promise
// then方法指定的回调函数，将在当前脚本所有同步任务执行完才会执行，所以resolved最后输出。

------------------------------------------------------------------
// 如果调用resolve函数和reject函数时带有参数，那么它们的参数会被传递给回调函数。
// reject函数的参数通常是Error对象的实例，表示抛出的错误；
// resolve函数的参数除了正常的值以外，还可能是另一个 Promise 实例。
const p1 = new Promise(function (resolve, reject) {
  // ...
});
const p2 = new Promise(function (resolve, reject) {
  // ...
  resolve(p1);
})
// p1和p2都是 Promise 的实例，p2的resolve方法将p1作为参数，
// 即一个异步操作的结果是返回另一个异步操作
// 这时p1的状态就会传递给p2，也就是说，p1的状态决定了p2的状态。
// 如果p1的状态是pending，那么p2的回调函数就会等待p1的状态改变；
// 如果p1的状态已经是resolved或者rejected，那么p2的回调函数将会立刻执行。

const p1 = new Promise(function (resolve, reject) {
  setTimeout(() => reject(new Error('fail')), 3000)
})
const p2 = new Promise(function (resolve, reject) {
  setTimeout(() => resolve(p1), 1000)
})
p2
  .then(result => console.log(result))
  .catch(error => console.log(error))
// Error: fail
// p1是一个 Promise，3 秒之后变为rejected。
// p2的状态在 1 秒之后改变，resolve方法返回的是p1。
// 由于p2返回的是另一个 Promise，导致p2自己的状态无效了，由p1的状态决定p2的状态。
// 所以，后面的then语句都变成针对后者（p1）。
// 又过了 2 秒，p1变为rejected，导致触发catch方法指定的回调函数。

-----------------------------------------------------------
// 调用resolve或reject并不会终结 Promise 的参数函数的执行。
new Promise((resolve, reject) => {
  resolve(1);
  console.log(2);
}).then(r => {
  console.log(r);
});
// 2
// 1
// 调用resolve(1)以后，后面的console.log(2)还是会执行，并且会首先打印出来。
// 这是因为立即 resolved 的 Promise 是在本轮事件循环的末尾执行，总是晚于本轮循环的同步任务。

------------------------------------------------------------
// 用resolve或reject以后，Promise 的使命就完成了，后继操作应该放到then方法里面，
// 而不应该直接写在resolve或reject的后面。
// 所以，最好在它们前面加上return语句，这样就不会有意外。
new Promise((resolve, reject) => {
  return resolve(1);
  // 后面的语句不会执行
  console.log(2);
})
```

# Promise.prototype.then()
1. then方法的第一个参数是resolved状态的回调函数，
2. then方法的第二个参数（可选）是rejected状态的回调函数。
3. then方法返回的是一个新的Promise实例（注意，不是原来那个Promise实例）。
4. 因此可以采用链式写法，即then方法后面再调用另一个then方法。
``` bash

getJSON("/posts.json").then(function(json) {
  return json.post;
}).then(function(post) {
  // ...
});
// 采用链式的then，可以指定一组按照次序调用的回调函数。
// 上面的代码使用then方法，依次指定了两个回调函数。
// 第一个回调函数完成以后，会将返回结果作为参数，传入第二个回调函数。

----------------------------------------------------------
// 采用链式的then，可以指定一组按照次序调用的回调函数。
// 这时，前一个回调函数，有可能返回的还是一个Promise对象（即有异步操作）
// 这时后一个回调函数，就会等待该Promise对象的状态发生变化，才会被调用。
getJSON("/post/1.json").then(function(post) {
  return getJSON(post.commentURL);
}).then(function funcA(comments) {
  console.log("resolved: ", comments);
}, function funcB(err){
  console.log("rejected: ", err);
});
// 第一个then方法指定的回调函数，返回的是另一个Promise对象。
// 这时，第二个then方法指定的回调函数，就会等待这个新的Promise对象状态发生变化。
// 如果变为resolved，就调用funcA，如果状态变为rejected，就调用funcB。
```

# Promise.prototype.catch()
1. Promise.prototype.catch方法是.then(null, rejection)的别名，用于指定发生错误时的回调函数。
``` bash

getJSON('/posts.json').then(function(posts) {
  // ...
}).catch(function(error) {
  // 处理 getJSON 和 前一个回调函数运行时发生的错误
  console.log('发生错误！', error);
});
// 上面代码中，getJSON方法返回一个 Promise 对象，
// 如果该对象状态变为resolved，则会调用then方法指定的回调函数；
// 如果异步操作抛出错误，状态就会变为rejected，就会调用catch方法指定的回调函数，处理这个错误。
// 另外，then方法指定的回调函数，如果运行中抛出错误，也会被catch方法捕获

------------------------------------------------------------------
const promise = new Promise(function(resolve, reject) {
  throw new Error('test');
});
promise.catch(function(error) {
  console.log(error);
});
// Error: test
// promise抛出一个错误，就被catch方法指定的回调函数捕获，上面的写法与下面两种写法是等价的

// 写法一
const promise = new Promise(function(resolve, reject) {
  try {
    throw new Error('test');
  } catch(e) {
    reject(e);
  }
});
promise.catch(function(error) {
  console.log(error);
});

// 写法二
const promise = new Promise(function(resolve, reject) {
  reject(new Error('test'));
});
promise.catch(function(error) {
  console.log(error);
});
// reject方法的作用，等同于抛出错误。

-----------------------------------------------------------------
// 如果 Promise 状态已经变成resolved，再抛出错误，是不会被捕获，等于没有抛出。
// 因为 Promise 的状态一旦改变，就永久保持该状态，不会再变了。
const promise = new Promise(function(resolve, reject) {
  resolve('ok');
  throw new Error('test');
});
promise
  .then(function(value) { console.log(value) })
  .catch(function(error) { console.log(error) });
// ok

---------------------------------------------------------------
// Promise 对象的错误具有“冒泡”性质，会一直向后传递，直到被捕获为止。
// 也就是说，错误总是会被下一个catch语句捕获。
getJSON('/post/1.json').then(function(post) {
  return getJSON(post.commentURL);
}).then(function(comments) {
  // some code
}).catch(function(error) {
  // 处理前面三个Promise产生的错误
});
// 上面代码中，一共有三个 Promise 对象：一个由getJSON产生，两个由then产生。
// 它们之中任何一个抛出的错误，都会被最后一个catch捕获。

----------------------------------------------------------------
// 一般来说，总是使用catch方法，而不使用then方法的第二个参数。
// 理由是catch方法可以捕获前面then方法执行中的错误，也更接近同步的写法（try/catch）
// bad
promise
  .then(function(data) {
    // success
  }, function(err) {
    // error
  });

// good
promise
  .then(function(data) { //cb
    // success
  })
  .catch(function(err) {
    // error
  });

------------------------------------------------------------------------------  
// 跟传统的try/catch代码块不同的是，如果没有使用catch方法指定错误处理的回调函数，
// Promise 对象抛出的错误不会传递到外层代码。
const someAsyncThing = function() {
  return new Promise(function(resolve, reject) {
    resolve(x + 2); // 报错，因为x没有声明
  });
};
someAsyncThing().then(function() {
  console.log('everything is great');
});
setTimeout(() => { console.log(123) }, 2000);
// Uncaught (in promise) ReferenceError: x is not defined
// 123

// someAsyncThing函数产生的 Promise 对象，内部有语法错误。
// 浏览器运行到这一行，会打印出错误提示ReferenceError: x is not defined，
// 但是不会退出进程、终止脚本执行，2 秒之后还是会输出123。
// 这就是说，Promise 内部的错误不会影响到 Promise 外部的代码，
// 通俗的说法就是“Promise 会吃掉错误”。

-------------------------------------------------------------------------
const promise = new Promise(function (resolve, reject) {
  resolve('ok');
  setTimeout(function () { throw new Error('test') }, 0)
});
promise.then(function (value) { console.log(value) });
// ok
// Uncaught Error: test
// Promise 指定在下一轮“事件循环”再抛出错误。到了那个时候，Promise 的运行已经结束了，
// 所以这个错误是在 Promise 函数体外抛出的，会冒泡到最外层，成了未捕获的错误。

-------------------------------------------------------------
// Promise 对象后面要跟catch方法，这样可以处理 Promise 内部发生的错误。
// catch方法返回的还是一个 Promise 对象，因此后面还可以接着调用then方法。
const someAsyncThing = function() {
  return new Promise(function(resolve, reject) {
    resolve(x + 2); // 会报错，因为x没有声明
  });
};
someAsyncThing().catch(function(error) {
  console.log('oh no', error);
})
.then(function() {
  console.log('carry on');
});
// oh no [ReferenceError: x is not defined]
// carry on
// 上面代码运行完catch方法指定的回调函数，会接着运行后面那个then方法指定的回调函数。

------------------------------------------------------------
// catch方法之中，还能再抛出错误。
const someAsyncThing = function() {
  return new Promise(function(resolve, reject) {
    resolve(x + 2); // 会报错，因为x没有声明
  });
};
someAsyncThing().then(function() {
  return someOtherAsyncThing();
}).catch(function(error) {
  console.log('oh no', error);
  y + 2; // 会报错，因为y没有声明
}).catch(function(error) {
  console.log('carry on', error);
});
// oh no [ReferenceError: x is not defined]
// carry on [ReferenceError: y is not defined]
// 第二个catch方法用来捕获前一个catch方法抛出的错误
```

# Promise.prototype.finally()
1. finally方法用于指定不管 Promise 对象最后状态如何，都会执行的操作。
2. finally方法的回调函数不接受任何参数，这意味着没有办法知道，前面的 Promise 状态到底是fulfilled还是rejected。
3. 这表明，finally方法里面的操作，应该是与状态无关的，不依赖于 Promise 的执行结果。
``` bash
promise
.then(result => {···})
.catch(error => {···})
.finally(() => {···});

// finally本质上是then方法的特例。
promise.finally(() => {
  // 语句
});

// 等同于
promise.then(
  result => {
    // 语句
    return result;
  },
  error => {
    // 语句
    throw error;
  }
);
```

# Promise.all()
1. Promise.all方法用于将多个Promise实例，包装成一个新的Promise实例，
2. 传递的参数是一个由多个Promise实例组成的数组
3. 如果数组的成员不是Promise实例，就会先调用Promise.resolve方法，将其转为 Promise 实例，再进一步处理。
4. Promise.all方法的参数可以不是数组，但必须具有 Iterator 接口，且返回的每个成员都是 Promise 实例。
``` bash
const p = Promise.all([p1, p2, p3]);

// p的状态由p1、p2、p3决定，分成两种情况。
// p1、p2、p3的状态都变成fulfilled，p的状态才会变成fulfilled，此时p1、p2、p3的返回值组成一个数组，传递给p的回调函数。
// 只要p1、p2、p3之中有一个被rejected，p的状态就变成rejected，此时第一个被reject的实例的返回值，会传递给p的回调函数。
```

``` bash

// 生成一个Promise对象的数组
const promises = [2, 3, 5, 7, 11, 13].map(function (id) {
  return getJSON('/post/' + id + ".json");
});
Promise.all(promises).then(function (posts) {
  // ...
}).catch(function(reason){
  // ...
});
// 只有这 6 个实例的状态都变成fulfilled，或者其中有一个变为rejected，
// 才会调用Promise.all方法后面的回调函数。

---------------------------------------
const databasePromise = connectDatabase();
const booksPromise = databasePromise.then(findAllBooks);
const userPromise = databasePromise.then(getCurrentUser);

Promise.all([
  booksPromise,
  userPromise
]).then(([books, user]) => pickTopRecommentations(books, user));

// booksPromise和userPromise是两个异步操作，只有等到它们的结果都返回了，
// 才会触发pickTopRecommentations这个回调函数。

----------------------------------------------
// 如果作为参数的 Promise 实例，自己定义了catch方法，
// 那么它一旦被rejected，并不会触发Promise.all()的catch方法
const p1 = new Promise((resolve, reject) => {
  resolve('hello');
}).then(result => result).catch(e => e);

const p2 = new Promise((resolve, reject) => {
  throw new Error('报错了');
}).then(result => result).catch(e => e);

Promise.all([p1, p2])
.then(result => console.log(result))
.catch(e => console.log(e));

// ["hello", Error: 报错了]

// p1会resolved，
// p2首先会rejected，但是p2有自己的catch方法，该方法返回的是一个新的 Promise 实例，
// p2指向的实际上是这个实例。该实例执行完catch方法后，也会变成resolved，
// 导致Promise.all()方法参数里面的两个实例都会resolved，因此会调用then方法指定的回调函数，
// 而不会调用catch方法指定的回调函数。

// 如果p2没有自己的catch方法，就会调用Promise.all()的catch方法。
const p1 = new Promise((resolve, reject) => {
  resolve('hello');
}).then(result => result);

const p2 = new Promise((resolve, reject) => {
  throw new Error('报错了');
}).then(result => result);

Promise.all([p1, p2])
.then(result => console.log(result))
.catch(e => console.log(e));
// Error: 报错了

```

# Promise.race()
``` bash
const p = Promise.race([p1, p2, p3]);
```
1. Promise.race方法同样是将多个 Promise 实例，包装成一个新的 Promise 实例。
2. Promise.race方法的参数的成员如果不是 Promise 实例，就会先调用Promise.resolve方法，将参数转为 Promise 实例，再进一步处理。
3. 只要p1、p2、p3之中有一个实例率先改变状态，p的状态就跟着改变。那个率先改变的 Promise 实例的返回值，就传递给p的回调函数。
``` bash
// 如果指定时间内没有获得结果，就将 Promise 的状态变为reject，否则变为resolve。
const p = Promise.race([
  fetch('/resource-that-may-take-a-while'),
  new Promise(function (resolve, reject) {
    setTimeout(() => reject(new Error('request timeout')), 5000)
  })
]);
p.then(console.log).catch(console.error);
// 如果 5 秒之内fetch方法无法返回结果，变量p的状态就会变为rejected，
// 从而触发catch方法指定的回调函数。
```

# Promise.resolve()
将现有对象转为 Promise 对象
``` bash
const jsPromise = Promise.resolve($.ajax('/whatever.json'));
// 将 jQuery 生成的deferred对象，转为一个新的 Promise 对象
```
Promise.resolve方法的参数分成四种情况:
1. 如果参数是 Promise 实例，那么Promise.resolve将不做任何修改、原封不动地返回这个实例。
2. 参数是一个thenable对象
3. 参数不是具有then方法的对象，或根本就不是对象
4. 不带有任何参数
``` bash

var b = new Promise((resolve, reject) => {
    setTimeout(() => {reject('xxxxxx')}, 3000)
});
Promise.resolve(b)
.then((data) => {console.log(data)})
.catch((data) => {console.log('catch', data)});
// catch xxxxxx

// Promise.resolve(b)：Promise.resolve不会改变b的状态，3秒后b会变成reject

--------------------------------------------------
// thenable对象指的是具有then方法的对象，比如下面这个对象。
let thenable = {
  then: function(resolve, reject) {
    resolve(42);
  }
};

// Promise.resolve方法会将这个对象转为 Promise 对象，然后就立即执行thenable对象的then方法。
let thenable = {
  then: function(resolve, reject) {
    resolve(42);
  }
};
let p1 = Promise.resolve(thenable);
p1.then(function(value) {
  console.log(value);  // 42
});
// thenable对象的then方法执行后，对象p1的状态就变为resolved，
// 从而立即执行最后那个then方法指定的回调函数，输出 42。

---------------------------------------------------------
// 如果参数是一个原始值，或者是一个不具有then方法的对象，
// 则Promise.resolve方法返回一个新的 Promise 对象，状态为resolved。
const p = Promise.resolve('Hello');
p.then(function (s){
  console.log(s)
});
// Hello
// 由于字符串Hello不属于异步操作（判断方法是字符串对象不具有 then 方法），
// 返回 Promise 实例的状态从一生成就是resolved，所以回调函数会立即执行。
// Promise.resolve方法的参数，会同时传给回调函数。

---------------------------------------------------------
// Promise.resolve方法允许调用时不带参数，直接返回一个resolved状态的 Promise 对象
const p = Promise.resolve();
p.then(function () {
  // ...
});

// 立即resolve的 Promise 对象，是在本轮“事件循环”（event loop）的结束时，
// 而不是在下一轮“事件循环”的开始时。
setTimeout(function () {
  console.log('three');
}, 0);

Promise.resolve().then(function () {
  console.log('two');
});

console.log('one');

// one
// two
// three

// setTimeout(fn, 0)在下一轮“事件循环”开始时执行，
// Promise.resolve()在本轮“事件循环”结束时执行，
// console.log('one')则是立即执行，因此最先输出
```

# Promise.reject()
1. Promise.reject(reason)方法也会返回一个新的 Promise 实例，该实例的状态为rejected
2. Promise.reject()方法的参数，会原封不动地作为reject的理由，变成后续方法的参数。这一点与Promise.resolve方法不一致。
``` bash

const p = Promise.reject('出错了');
// 等同于
const p = new Promise((resolve, reject) => reject('出错了'))
p.then(null, function (s) {
  console.log(s)
});
// 出错了

-----------------------------------------------------
var b = new Promise((resolve, reject) => {
    setTimeout(() => {resolve('xxxxxx')}, 3000)
});
Promise.reject(b)
.then((data) => {console.log(data)})
.catch((data) => {console.log('catch', data)});
// catch Promise {<pending>}

// Promise.reject(b): 返回状态为rejected的Promise实例，
// b原封不动地作为reject的理由，作为catch 回调的参数

-------------------------------------------------------
const thenable = {
  then(resolve, reject) {
    reject('出错了');
  }
};
Promise.reject(thenable)
.catch(e => {
  console.log(e === thenable)
})
// true
// Promise.reject方法的参数是一个thenable对象，
// 执行以后，后面catch方法的参数不是reject抛出的“出错了”这个字符串，而是thenable对象。
```

# Promise.try()
> 不知道或者不想区分，函数f是同步函数还是异步操作，但是想用 Promise 来处理它，
> 并且让同步函数同步执行，异步函数异步执行，并且具有统一的API
``` bash

// 问题引出
const f = () => console.log('now');
Promise.resolve().then(f);
console.log('next');
// next
// now
// 缺点，就是如果f是同步函数，那么它会在本轮事件循环的末尾执行
// 函数f是同步的，但是用 Promise 包装了以后，就变成异步执行了

---------------------------------------------------------------
// 解决办法1
const f = () => console.log('now');
(async () => f())();
console.log('next');
// now
// next
// 第二行是一个立即执行的匿名函数，会立即执行里面的async函数，
// 因此如果f是同步的，就会得到同步的结果；
// 如果f是异步的，就可以用then指定下一步，就像下面的写法。
(async () => f())().then(...).catch(...)

------------------------------------------------
// 解决办法2
const f = () => console.log('now');
(() => new Promise(
    resolve => resolve(f())
))();
console.log('next');
// now
// next
// 上面代码也是使用立即执行的匿名函数，执行new Promise()。
// 这种情况下，同步函数也是同步执行的。 

----------------------------------------------------
// Promise.try方法替代上面的写法
const f = () => console.log('now');
Promise.try(f);
console.log('next');
// now
// next
// 同步函数同步执行，异步函数异步执行

// Promise.try存在已久，Promise 库Bluebird、Q和when，早就提供了这个方法
// Promise.try为所有操作提供了统一的处理机制，所以如果想用then方法管理流程，
// 最好都用Promise.try包装一下

// 没有处理错误
function getUsername(userId) {
  return database.users.get({id: userId}).then(function(user) {
    return user.name;
  });
}

// 处理Promise和then回调的错误
database.users.get({id: userId}).then(...).catch(...)

// 繁琐的处理错误
function getUsername(userId) {
  try {
    database.users.get({id: userId})
    .then(...)
    .catch(...) // 处理Promise和then回调的错误
  } catch (e) {
    // 处理没有考虑到的其他错误
  }
}

// 一次性处理所有的错误
// 不想区分database.users.get({id: userId})是否异步，同步函数同步执行，异步函数异步执行
Promise.try(database.users.get({id: userId}))
.then(...)
.catch(...)

```

# Promise 的应用
``` bash

// 异步加载图片的例子
function loadImageAsync(url) {
  return new Promise(function(resolve, reject) {
    const image = new Image();
    image.onload = function() { resolve(image); };
    image.onerror = function() { reject(new Error('Could not load image at ' + url)); };
    image.src = url;
  });
}

----------------------------------------------------------
// Promise对象实现的 Ajax 操作的例子
const getJSON = function(url) {
  const promise = new Promise(function(resolve, reject){
    const handler = function() {
      if (this.readyState !== 4) {
        return;
      }
      if (this.status === 200) {
        resolve(this.response);
      } else {
        reject(new Error(this.statusText));
      }
    };
    const client = new XMLHttpRequest();
    client.open("GET", url);
    client.onreadystatechange = handler;
    client.responseType = "json";
    client.setRequestHeader("Accept", "application/json");
    client.send();
  });
  return promise;
};

getJSON("/posts.json").then(function(json) {
  console.log('Contents: ' + json);
}, function(error) {
  console.error('出错了', error);
});

--------------------------------------------------------
// 使用 Generator 函数管理流程，遇到异步操作的时候，通常返回一个Promise对象。
function getFoo () {
  return new Promise(function (resolve, reject){
    resolve('foo');
  });
}
const g = function* () {
  try {
    const foo = yield getFoo();
    console.log(foo);
  } catch (e) {
    console.log(e);
  }
};
function run (generator) {
  const it = generator();
  function go(result) {
    if (result.done) return result.value;
    return result.value.then(function (value) {
      return go(it.next(value));
    }, function (error) {
      return go(it.throw(error));
    });
  }
  go(it.next());
}
run(g);

// 上面代码的 Generator 函数g之中，有一个异步操作getFoo，它返回的就是一个Promise对象。
// 函数run用来处理这个Promise对象，并调用下一个next方法。

```